<?xml version="1.0" ?>
<robot name="2v2_70.30_70.30_1.1_73">

    <link name="palm">
        <visual>
            <origin rpy="0 0 0" xyz="0 0 0"/>
            <geometry>
                <mesh filename="obj_files/palm.obj" scale="1 1 1"/>
            </geometry>
        </visual>
        <collision>
            <geometry>
                <mesh filename="obj_files/palm_collision.obj" scale="1 1 1"/>
            </geometry>
        </collision>
    </link>

    <link name="finger0_segment0">
        <visual>
            <origin rpy="0 0 0" xyz="0 0 0"/>
            <geometry>
                <mesh filename="obj_files/finger0_segment0.obj" scale="1 1 1"/>
            </geometry>
        </visual>
        <collision>
            <geometry>
                <mesh filename="obj_files/finger0_segment0_collision.obj" scale="1 1 1"/>
            </geometry>
        </collision>
    </link>

    <joint name="finger0_segment0_joint" type="revolute">
        <parent link="palm"/>
        <child link="finger0_segment0"/>
        <origin rpy="0 0 0" xyz="0.03675 0 0.0"/>
        <axis xyz="0 0 1"/>
        <limit effort="1000.0" lower="-3.14" upper="3.14" velocity="0.5"/>
    </joint>

    <link name="finger0_segment1">
        <visual>
            <origin rpy="0 0 0" xyz="0 0 0"/>
            <geometry>
                <mesh filename="obj_files/finger0_segment1.obj" scale="1 1 1"/>
            </geometry>
        </visual>
        <collision>
            <geometry>
                <mesh filename="obj_files/finger0_segment1_collision.obj" scale="1 1 1"/>
            </geometry>
        </collision>
    </link>

    <joint name="finger0_segment1_joint" type="revolute">
        <parent link="finger0_segment0"/>
        <child link="finger0_segment1"/>
        <origin rpy="0 0 0" xyz="0 0.1008 0"/>
        <axis xyz="0 0 1"/>
        <limit effort="1000.0" lower="-3.14" upper="3.14" velocity="0.5"/>
    </joint>

    <link name="finger1_segment0">
        <visual>
            <origin rpy="0 0 0" xyz="0 0 0"/>
            <geometry>
                <mesh filename="obj_files/finger1_segment0.obj" scale="1 1 1"/>
            </geometry>
        </visual>
        <collision>
            <geometry>
                <mesh filename="obj_files/finger1_segment0_collision.obj" scale="1 1 1"/>
            </geometry>
        </collision>
    </link>

    <joint name="finger1_segment0_joint" type="revolute">
        <parent link="palm"/>
        <child link="finger1_segment0"/>
        <origin rpy="0 0 0" xyz="-0.03675 0 4.500576986866523e-18"/>
        <axis xyz="0 0 1"/>
        <limit effort="1000.0" lower="-3.14" upper="3.14" velocity="0.5"/>
    </joint>

    <link name="finger1_segment1">
        <visual>
            <origin rpy="0 0 0" xyz="0 0 0"/>
            <geometry>
                <mesh filename="obj_files/finger1_segment1.obj" scale="1 1 1"/>
            </geometry>
        </visual>
        <collision>
            <geometry>
                <mesh filename="obj_files/finger1_segment1_collision.obj" scale="1 1 1"/>
            </geometry>
        </collision>
    </link>

    <joint name="finger1_segment1_joint" type="revolute">
        <parent link="finger1_segment0"/>
        <child link="finger1_segment1"/>
        <origin rpy="0 0 0" xyz="0 0.1008 0"/>
        <axis xyz="0 0 1"/>
        <limit effort="1000.0" lower="-3.14" upper="3.14" velocity="0.5"/>
    </joint>

</robot>