<?xml version="1.0" ?>
<robot name="2v2_70.30_50.50_1.1_53">

    <link name="palm">
        <visual>
            <origin rpy="0 0 0" xyz="0 0 0"/>
            <geometry>
                <mesh filename="obj_files/palm.obj" scale="1 1 1"/>
            </geometry>
        </visual>
        <collision>
            <geometry>
                <mesh filename="obj_files/palm_collision.obj" scale="1 1 1"/>
            </geometry>
        </collision>
        <inertial>
            <mass value="1"/>
            <inertia ixx="0.4" ixy="0.0" ixz="0.0" iyy="0.4" iyz="0.0" izz="0.2"/>
        </inertial>
    </link>

    <link name="finger0_segment0">
        <visual>
            <origin rpy="0 0 0" xyz="0 0 0"/>
            <geometry>
                <mesh filename="obj_files/finger0_segment0.obj" scale="1 1 1"/>
            </geometry>
        </visual>
        <collision>
            <geometry>
                <mesh filename="obj_files/finger0_segment0_collision.obj" scale="1 1 1"/>
            </geometry>
        </collision>
        <inertial>
            <mass value="0.1"/>
            <inertia ixx="0.4" ixy="0.0" ixz="0.0" iyy="0.4" iyz="0.0" izz="0.2"/>
        </inertial>
    </link>

    <joint name="finger0_segment0_joint" type="revolute">
        <parent link="palm"/>
        <child link="finger0_segment0"/>
        <origin rpy="0 0 0" xyz="0.02675 0 0.0"/>
        <axis xyz="0 0 1"/>
        <limit effort="1000.0" lower="-3.14" upper="3.14" velocity="0.5"/>
    </joint>

    <link name="finger0_segment1">
        <visual>
            <origin rpy="0 0 0" xyz="0 0 0"/>
            <geometry>
                <mesh filename="obj_files/finger0_segment1.obj" scale="1 1 1"/>
            </geometry>
        </visual>
        <collision>
            <geometry>
                <mesh filename="obj_files/finger0_segment1_collision.obj" scale="1 1 1"/>
            </geometry>
        </collision>
        <inertial>
            <mass value="0.1"/>
            <inertia ixx="0.4" ixy="0.0" ixz="0.0" iyy="0.4" iyz="0.0" izz="0.2"/>
        </inertial>
    </link>

    <joint name="finger0_segment1_joint" type="revolute">
        <parent link="finger0_segment0"/>
        <child link="finger0_segment1"/>
        <origin rpy="0 0 0" xyz="0 0.1008 0"/>
        <axis xyz="0 0 1"/>
        <limit effort="1000.0" lower="-3.14" upper="3.14" velocity="0.5"/>
    </joint>

    <link name="finger1_segment0">
        <visual>
            <origin rpy="0 0 0" xyz="0 0 0"/>
            <geometry>
                <mesh filename="obj_files/finger1_segment0.obj" scale="1 1 1"/>
            </geometry>
        </visual>
        <collision>
            <geometry>
                <mesh filename="obj_files/finger1_segment0_collision.obj" scale="1 1 1"/>
            </geometry>
        </collision>
        <inertial>
            <mass value="0.1"/>
            <inertia ixx="0.4" ixy="0.0" ixz="0.0" iyy="0.4" iyz="0.0" izz="0.2"/>
        </inertial>
    </link>

    <joint name="finger1_segment0_joint" type="revolute">
        <parent link="palm"/>
        <child link="finger1_segment0"/>
        <origin rpy="0 0 0" xyz="-0.02675 0 3.27593018771917e-18"/>
        <axis xyz="0 0 1"/>
        <limit effort="1000.0" lower="-3.14" upper="3.14" velocity="0.5"/>
    </joint>

    <link name="finger1_segment1">
        <visual>
            <origin rpy="0 0 0" xyz="0 0 0"/>
            <geometry>
                <mesh filename="obj_files/finger1_segment1.obj" scale="1 1 1"/>
            </geometry>
        </visual>
        <collision>
            <geometry>
                <mesh filename="obj_files/finger1_segment1_collision.obj" scale="1 1 1"/>
            </geometry>
        </collision>
        <inertial>
            <mass value="0.1"/>
            <inertia ixx="0.4" ixy="0.0" ixz="0.0" iyy="0.4" iyz="0.0" izz="0.2"/>
        </inertial>
    </link>

    <joint name="finger1_segment1_joint" type="revolute">
        <parent link="finger1_segment0"/>
        <child link="finger1_segment1"/>
        <origin rpy="0 0 0" xyz="0 0.072 0"/>
        <axis xyz="0 0 1"/>
        <limit effort="1000.0" lower="-3.14" upper="3.14" velocity="0.5"/>
    </joint>
    <link name="finger0_sensor">
        <inertial>
            <mass value="0.000001"/>
            <inertia ixx="0.000004" ixy="0.0" ixz="0.0" iyy="0.000004" iyz="0.0" izz="0.000002"/>
        </inertial>
    </link>

    <joint name="finger0_sensor1_joint" type="fixed">
        <parent link="finger0_segment1"/>
        <child link="finger0_sensor"/>
        <origin rpy="0 0 0" xyz="0 0.072 0"/>
        <axis xyz="0 0 1"/>
        <limit effort="1000.0" lower="-3.14" upper="3.14" velocity="0.5"/>
    </joint>


    <link name="finger1_sensor">
        <inertial>
            <mass value="0.000001"/>
            <inertia ixx="0.000004" ixy="0.0" ixz="0.0" iyy="0.000004" iyz="0.0" izz="0.000002"/>
        </inertial>
    </link>

    <joint name="finger1_sensor2_joint" type="fixed">
        <parent link="finger1_segment1"/>
        <child link="finger1_sensor"/>
        <origin rpy="0 0 0" xyz="0 0.072 0"/>
        <axis xyz="0 0 1"/>
        <limit effort="1000.0" lower="-3.14" upper="3.14" velocity="0.5"/>
    </joint>
</robot>
