<?xml version="1.0" ?>
<robot name="miranda_underact_2v2">

    <link name="body_palm_lpinvrpin">
        <visual>
            <origin rpy="0 1.5707963267948966 0" xyz="0 0 0"/>
            <geometry>
                <mesh filename="obj_files/body_palm_lpinvrpin.obj" scale="1 1 1"/>
            </geometry>
        </visual>
        <collision>
            <geometry>
                <mesh filename="obj_files/body_palm_lpinvrpin_collision.obj" scale="1 1 1"/>
            </geometry>
        </collision>
    </link>

    <joint name="l_proximal_pin" type="revolute">
        <parent link="body_palm_lpinvrpin"/>
        <child link="body_l_proximal_pinvspring"/>
        <origin rpy="0 0 0" xyz="-0.039 0.058 0"/>
        <axis xyz="0 0 1"/>
        <limit effort="1000.0" lower="-3.14" upper="3.14" velocity="0.5"/>
    </joint>

    <link name="body_l_proximal_pinvspring">
        <visual>
            <origin rpy="0 1.5707963267948966 0" xyz="0 0 0"/>
            <geometry>
                <mesh filename="obj_files/body_l_proximal_pinvspring.obj" scale="1 1 1"/>
            </geometry>
        </visual>
        <collision>
            <geometry>
                <mesh filename="obj_files/body_l_proximal_pinvspring_collision.obj" scale="1 1 1"/>
            </geometry>
        </collision>
    </link>

    <joint name="l_distal_spring" type="revolute">
        <parent link="body_l_proximal_pinvspring"/>
        <child link="body_l_distal_springvround"/>
        <origin rpy="0 0 0" xyz="0 0.08582500000000001 0"/>
        <axis xyz="0 0 1"/>
        <limit effort="1000.0" lower="-3.14" upper="3.14" velocity="0.5"/>
    </joint>

    <link name="body_l_distal_springvround">
        <visual>
            <origin rpy="0 1.5707963267948966 0" xyz="0 0 0"/>
            <geometry>
                <mesh filename="obj_files/body_l_distal_springvround.obj" scale="1 1 1"/>
            </geometry>
        </visual>
        <collision>
            <geometry>
                <mesh filename="obj_files/body_l_distal_springvround_collision.obj" scale="1 1 1"/>
            </geometry>
        </collision>
    </link>

    <joint name="r_proximal_pin" type="revolute">
        <parent link="body_palm_lpinvrpin"/>
        <child link="body_r_proximal_pinvspring"/>
        <origin rpy="0 0 0" xyz="0.039 0.058 0"/>
        <axis xyz="0 0 1"/>
        <limit effort="1000.0" lower="-3.14" upper="3.14" velocity="0.5"/>
    </joint>

    <link name="body_r_proximal_pinvspring">
        <visual>
            <origin rpy="0 1.5707963267948966 0" xyz="0 0 0"/>
            <geometry>
                <mesh filename="obj_files/body_r_proximal_pinvspring.obj" scale="1 1 1"/>
            </geometry>
        </visual>
        <collision>
            <geometry>
                <mesh filename="obj_files/body_r_proximal_pinvspring_collision.obj" scale="1 1 1"/>
            </geometry>
        </collision>
    </link>

    <joint name="r_distal_spring" type="revolute">
        <parent link="body_r_proximal_pinvspring"/>
        <child link="body_r_distal_springvround"/>
        <origin rpy="0 0 0" xyz="0 0.08582500000000001 0"/>
        <axis xyz="0 0 1"/>
        <limit effort="1000.0" lower="-3.14" upper="3.14" velocity="0.5"/>
    </joint>

    <link name="body_r_distal_springvround">
        <visual>
            <origin rpy="0 1.5707963267948966 0" xyz="0 0 0"/>
            <geometry>
                <mesh filename="obj_files/body_r_distal_springvround.obj" scale="1 1 1"/>
            </geometry>
        </visual>
        <collision>
            <geometry>
                <mesh filename="obj_files/body_r_distal_springvround_collision.obj" scale="1 1 1"/>
            </geometry>
        </collision>
    </link>

</robot>